Sure, let's explore "Exceptions and Exception Handling" deeply in C#, drawing extensively from the principles and examples commonly found in Microsoft's official documentation. Exception handling is a critical aspect of building robust and reliable applications. It provides a structured way to deal with unexpected or erroneous situations that can occur during program execution, preventing applications from crashing abruptly.

## Exceptions and Exception Handling: A Deep Dive

**Concept:**
An **exception** is an event that disrupts the normal flow of a program. It's an indication that an error or an unexpected condition has occurred during the execution of code. In C#, exceptions are objects that encapsulate information about the error, such as its type, a message, and the stack trace (where the error occurred).

**Exception Handling** is the process of responding to these exceptions. It involves writing code that anticipates potential errors, detects when they occur, and takes appropriate action to recover, inform the user, log the error, or gracefully terminate the program. C# provides a structured mechanism for this using `try`, `catch`, `finally`, and `throw` keywords.

**Why is Exception Handling Essential?**

1.  **Robustness:** Prevents applications from crashing due to unexpected inputs, missing files, network issues, invalid operations, etc.
2.  **Graceful Degradation:** Allows the application to continue running, perhaps in a limited capacity, even when errors occur.
3.  **User Experience:** Provides meaningful error messages to users instead of cryptic system errors or program crashes.
4.  **Debugging and Logging:** Captures detailed error information (stack trace, message, inner exceptions) that is invaluable for debugging and logging.
5.  **Separation of Concerns:** Separates the "normal" program logic from the "error handling" logic, making both cleaner and easier to manage.

### The Anatomy of Exception Handling in C#:

The core constructs for exception handling in C# are:

* **`try` block:** Encloses a block of code that might throw an exception.
* **`catch` block:** Handles a specific type of exception (or any exception) that is thrown within the associated `try` block. A `try` block can have multiple `catch` blocks.
* **`finally` block:** Contains code that is guaranteed to execute, whether an exception occurred or not. It's typically used for cleanup operations (e.g., closing file streams, releasing database connections).
* **`throw` statement:** Used to explicitly raise an exception. This can be a new exception or a re-thrown exception.

### Deep Dive with Code Examples:

Let's illustrate these concepts with various scenarios.

#### 1. Basic `try-catch` Block

Handling a single, specific exception type.

```csharp
using System;
using System.IO; // For IOException, FileNotFoundException

namespace ExceptionHandlingDemo
{
    class BasicTryCatch
    {
        public static void Divide(int numerator, int denominator)
        {
            Console.WriteLine($"\n--- Attempting division: {numerator} / {denominator} ---");
            try
            {
                // This code might throw a DivideByZeroException
                int result = numerator / denominator;
                Console.WriteLine($"Result: {result}");
            }
            catch (DivideByZeroException ex) // Catches only DivideByZeroException
            {
                Console.WriteLine($"Error: Cannot divide by zero. Message: {ex.Message}");
                // You can also log the exception details here:
                // Log.Error($"DivideByZeroException occurred: {ex.Message}", ex);
            }
            // If any other exception occurs here, it will not be caught by this block
            // and will propagate up the call stack.
        }

        public static void ReadFile(string filePath)
        {
            Console.WriteLine($"\n--- Attempting to read file: {filePath} ---");
            try
            {
                string content = File.ReadAllText(filePath);
                Console.WriteLine($"File content (first 50 chars): {content.Substring(0, Math.Min(content.Length, 50))}");
            }
            catch (FileNotFoundException ex) // Catches specifically FileNotFoundException
            {
                Console.WriteLine($"Error: The file '{filePath}' was not found. Details: {ex.Message}");
            }
            catch (IOException ex) // Catches other I/O related errors
            {
                Console.WriteLine($"Error: An I/O error occurred while accessing '{filePath}'. Details: {ex.Message}");
            }
        }

        public static void Run()
        {
            Divide(10, 2);
            Divide(10, 0); // This will cause DivideByZeroException

            // Create a dummy file for success case
            string dummyFilePath = "temp_data.txt";
            File.WriteAllText(dummyFilePath, "This is some sample content for the file.");

            ReadFile(dummyFilePath);
            ReadFile("non_existent_file.txt"); // This will cause FileNotFoundException

            File.Delete(dummyFilePath); // Clean up the dummy file
        }
    }
}
```

#### 2. Multiple `catch` Blocks and Order of Catching

When using multiple `catch` blocks, they should be ordered from most specific to least specific exception type. This is because a more general `catch` block (e.g., `catch (Exception)`) would catch all exceptions, preventing more specific handlers from ever being reached.

```csharp
using System;
using System.IO;

namespace ExceptionHandlingDemo
{
    class MultipleCatchBlocks
    {
        public static void ProcessInput(string input)
        {
            Console.WriteLine($"\n--- Processing input: '{input}' ---");
            try
            {
                if (input == null)
                {
                    throw new ArgumentNullException(nameof(input), "Input string cannot be null.");
                }
                if (input.Length < 5)
                {
                    throw new ArgumentException("Input string must be at least 5 characters long.", nameof(input));
                }
                int value = int.Parse(input); // Can throw FormatException or OverflowException
                Console.WriteLine($"Parsed value: {value}");

                // Simulate file access after parsing
                File.ReadAllText("non_existent_path\\file.txt"); // Could throw DirectoryNotFoundException
            }
            catch (FormatException ex) // Specific: for invalid number format
            {
                Console.WriteLine($"Catch (FormatException): Invalid number format. {ex.Message}");
            }
            catch (ArgumentException ex) // Specific: for invalid arguments (includes ArgumentNullException)
            {
                Console.WriteLine($"Catch (ArgumentException): Invalid argument provided. {ex.Message}");
            }
            catch (IOException ex) // More general I/O exception
            {
                Console.WriteLine($"Catch (IOException): An I/O error occurred. {ex.Message}");
            }
            catch (Exception ex) // Most general: catches any other exception
            {
                Console.WriteLine($"Catch (General Exception): An unexpected error occurred. Type: {ex.GetType().Name}, Message: {ex.Message}");
            }
        }

        public static void Run()
        {
            ProcessInput("123");       // Throws ArgumentException (length < 5)
            ProcessInput(null);        // Throws ArgumentNullException (caught by ArgumentException handler)
            ProcessInput("Hello World"); // Throws FormatException
            ProcessInput("123456789012345678901234567890"); // Could throw OverflowException
            ProcessInput("valid input for file error"); // Will trigger DirectoryNotFoundException (caught by IOException)
        }
    }
}
```

#### 3. The `finally` Block

Guarantees execution of code, regardless of whether an exception occurred or was caught. Ideal for releasing resources.

```csharp
using System;
using System.IO;

namespace ExceptionHandlingDemo
{
    class FinallyBlockDemo
    {
        public static void ReadAndCloseFile(string filePath)
        {
            FileStream? fs = null; // Use nullable type for FileStream
            Console.WriteLine($"\n--- Reading and closing file: {filePath} ---");
            try
            {
                fs = new FileStream(filePath, FileMode.Open);
                byte[] buffer = new byte[1024];
                int bytesRead = fs.Read(buffer, 0, buffer.Length);
                Console.WriteLine($"Read {bytesRead} bytes from file.");
            }
            catch (FileNotFoundException ex)
            {
                Console.WriteLine($"Error: File not found. {ex.Message}");
            }
            catch (Exception ex)
            {
                Console.WriteLine($"An unexpected error occurred: {ex.Message}");
            }
            finally // This block always executes
            {
                if (fs != null)
                {
                    fs.Close(); // Close the file stream
                    Console.WriteLine("File stream closed in finally block.");
                }
                else
                {
                    Console.WriteLine("File stream was not opened (or was null).");
                }
            }
            Console.WriteLine("Exited ReadAndCloseFile method.");
        }

        public static void Run()
        {
            // Create a dummy file for success case
            string dummyFilePath = "data.txt";
            File.WriteAllText(dummyFilePath, "This is some data for the file stream demonstration.");

            ReadAndCloseFile(dummyFilePath); // Successful read, finally executes
            ReadAndCloseFile("nonexistent.xyz"); // FileNotFound, finally executes
            // Simulate an error inside the try block (e.g., null reference)
            try
            {
                string? s = null;
                s!.Length.ToString(); // This will throw NullReferenceException
            }
            catch (Exception ex)
            {
                Console.WriteLine($"Caught in caller: {ex.Message}");
            }
            finally
            {
                Console.WriteLine("Finally block after NullReferenceException demo.");
            }

            File.Delete(dummyFilePath); // Clean up
        }
    }
}
```

#### 4. Throwing Exceptions

Explicitly raising an exception using the `throw` keyword. This is useful for validating inputs or business rules.

```csharp
using System;

namespace ExceptionHandlingDemo
{
    class ThrowingExceptions
    {
        public static void ProcessAge(int age)
        {
            if (age < 0 || age > 150)
            {
                // Throw a new ArgumentOutOfRangeException
                throw new ArgumentOutOfRangeException(nameof(age), $"Age must be between 0 and 150, but was {age}.");
            }
            Console.WriteLine($"Age {age} is valid.");
        }

        public static void ValidatePassword(string password)
        {
            if (string.IsNullOrWhiteSpace(password))
            {
                // Throw a custom exception (or ArgumentException)
                throw new ArgumentException("Password cannot be empty or whitespace.", nameof(password));
            }
            if (password.Length < 8)
            {
                throw new InvalidOperationException("Password must be at least 8 characters long.");
            }
            Console.WriteLine("Password is valid.");
        }

        public static void Run()
        {
            Console.WriteLine("\n--- Throwing Exceptions ---");
            try
            {
                ProcessAge(25);
                ProcessAge(-5); // This will throw ArgumentOutOfRangeException
                ProcessAge(200); // This line will not be reached
            }
            catch (ArgumentOutOfRangeException ex)
            {
                Console.WriteLine($"Caught: {ex.Message}");
            }

            try
            {
                ValidatePassword("short"); // This will throw InvalidOperationException
            }
            catch (InvalidOperationException ex)
            {
                Console.WriteLine($"Caught: {ex.Message}");
            }
            catch (ArgumentException ex) // Catches the case for null/empty password
            {
                Console.WriteLine($"Caught: {ex.Message}");
            }
        }
    }
}
```

#### 5. Re-throwing Exceptions

Sometimes you want to catch an exception, perform some action (like logging), and then re-throw the *original* exception to allow higher-level handlers to deal with it.

```csharp
using System;
using System.IO;

namespace ExceptionHandlingDemo
{
    class RethrowingExceptions
    {
        // Low-level method that might throw an exception
        public static void ReadConfig(string fileName)
        {
            Console.WriteLine($"\n--- Reading config: {fileName} ---");
            try
            {
                string content = File.ReadAllText(fileName);
                Console.WriteLine($"Config content: {content}");
            }
            catch (FileNotFoundException ex)
            {
                Console.WriteLine($"Logger: File '{fileName}' not found. Logging details...");
                // Log the exception here
                // Then re-throw the *original* exception.
                // 'throw;' preserves the original stack trace.
                // 'throw ex;' loses the original stack trace up to this point.
                throw;
            }
        }

        // Higher-level method that calls ReadConfig
        public static void LoadApplicationSettings()
        {
            Console.WriteLine("Loading application settings...");
            try
            {
                ReadConfig("appsettings.json");
            }
            catch (FileNotFoundException ex)
            {
                Console.WriteLine($"Application Setup: Critical error - config file missing. Exiting. Message: {ex.Message}");
                // Log and perhaps exit gracefully
                // Console.WriteLine(ex.StackTrace); // Observe the stack trace
            }
            catch (Exception ex)
            {
                Console.WriteLine($"Application Setup: An unexpected error occurred. Message: {ex.Message}");
            }
        }

        public static void Run()
        {
            LoadApplicationSettings();
        }
    }
}
```

**Important Note on `throw;` vs. `throw ex;`:**
* **`throw;`**: Re-throws the *original* exception, preserving the original stack trace. This is generally preferred when you want to handle an exception minimally (e.g., just log it) and then pass it up the call stack for further handling.
* **`throw ex;`**: Throws a *new* exception (even if it's the same object). This resets the stack trace to the point where `throw ex;` was executed, making it harder to debug the original source of the error. Only use this if you genuinely intend to start a new stack trace, perhaps after wrapping the original exception in a new, more descriptive one (`throw new CustomException("Something went wrong", ex);`).

#### 6. Custom Exceptions

You can define your own exception classes by deriving from `System.Exception` or one of its existing derived classes. This helps to make your exceptions more specific to your application's domain.

```csharp
using System;

namespace ExceptionHandlingDemo
{
    // Custom Exception: Indicates an invalid user input specific to our application
    public class InvalidUserException : Exception
    {
        public string InvalidUserName { get; }

        public InvalidUserException() : base("An invalid user was encountered.") { InvalidUserName = "N/A"; }
        public InvalidUserException(string message) : base(message) { InvalidUserName = "N/A"; }
        public InvalidUserException(string message, string userName) : base(message) { InvalidUserName = userName; }
        public InvalidUserException(string message, Exception innerException) : base(message, innerException) { InvalidUserName = "N/A"; }
        public InvalidUserException(string message, string userName, Exception innerException) : base(message, innerException) { InvalidUserName = userName; }
    }

    class CustomExceptionDemo
    {
        public static void AuthenticateUser(string username, string password)
        {
            Console.WriteLine($"\n--- Authenticating user: {username} ---");
            if (string.IsNullOrWhiteSpace(username) || string.IsNullOrWhiteSpace(password))
            {
                throw new ArgumentException("Username and password cannot be empty.");
            }

            if (username.ToLower() == "guest" || password.ToLower() == "password")
            {
                // Throw our custom exception
                throw new InvalidUserException("Invalid username or password for authentication.", username);
            }
            Console.WriteLine($"User '{username}' authenticated successfully.");
        }

        public static void Run()
        {
            try
            {
                AuthenticateUser("admin", "securepass");
                AuthenticateUser("guest", "12345"); // Throws InvalidUserException
            }
            catch (InvalidUserException ex)
            {
                Console.WriteLine($"Caught Custom Exception: {ex.Message}");
                Console.WriteLine($"Invalid User Name: {ex.InvalidUserName}");
            }
            catch (ArgumentException ex)
            {
                Console.WriteLine($"Caught ArgumentException: {ex.Message}");
            }
        }
    }
}
```

### Main Program to Run All Demos:

```csharp
using System;

namespace ExceptionHandlingDemo
{
    class Program
    {
        static void Main(string[] args)
        {
            Console.WriteLine("--- Exceptions and Exception Handling in C# ---");

            BasicTryCatch.Run();
            MultipleCatchBlocks.Run();
            FinallyBlockDemo.Run();
            ThrowingExceptions.Run();
            RethrowingExceptions.Run();
            CustomExceptionDemo.Run();

            Console.WriteLine("\n--- End of Exception Handling Demo ---");
            Console.ReadKey();
        }
    }
}
```

### Best Practices for Exception Handling:

* **Catch Specific Exceptions:** Don't just `catch (Exception ex)` always. Catch the most specific exception types first to handle them appropriately.
* **Handle vs. Re-throw:** If you can fully recover from an exception, handle it. If not, re-throw it (using `throw;`) after logging or performing minimal cleanup, allowing a higher-level component to manage it.
* **`finally` for Cleanup:** Always use `finally` to release resources (file handles, database connections, network sockets) to prevent resource leaks, regardless of whether an exception occurs.
* **Avoid Empty `catch` Blocks:** An empty `catch` block (a "swallow all" catch) hides errors and makes debugging extremely difficult. At the very least, log the exception.
* **Don't Use Exceptions for Flow Control:** Exceptions are for *exceptional* circumstances (errors, unexpected conditions), not for normal program flow control (e.g., using `try-catch` instead of `if-else` for validation).
* **Throw Early, Catch Late:** Throw exceptions as soon as an error is detected. Catch them at the appropriate level where you can genuinely recover or provide meaningful context to the user.
* **Provide Context:** When throwing exceptions, provide clear and concise messages. Include `innerException` when re-throwing to preserve the original error chain.
* **Use Standard Exceptions:** Reuse built-in .NET exceptions when they fit the error condition (e.g., `ArgumentException`, `InvalidOperationException`, `NullReferenceException`). Create custom exceptions only when standard ones don't adequately describe the error or when you need to add custom properties.

Exception handling is a cornerstone of writing robust C# applications. By understanding and correctly applying `try-catch-finally` blocks and exception best practices, you can build software that is resilient, user-friendly, and easier to debug and maintain.