Sure, let's explore "Exception Handling (C# Programming Guide)" deeply, with code examples drawn from Microsoft's documentation. This comprehensive guide synthesizes many concepts we've already covered (like `try-catch-finally`, `throw`, custom exceptions, and `using` statements for `IDisposable`), but within the broader context of C# programming, focusing on the **mechanism** itself and **best practices**.

The "Exception Handling (C# Programming Guide)" doc serves as the central hub for understanding *how* C# implements and manages exceptions, and *how* developers should interact with this system.

## Exception Handling (C# Programming Guide): A Deep Dive

**Core Concept:**
Exception handling in C# is a structured mechanism for detecting and responding to **runtime errors** or **exceptional conditions** that disrupt the normal execution flow of a program. It relies on the concept of "throwing" an exception when an error occurs and "catching" it at a point in the call stack where the error can be handled.

The C# exception handling model is based on the **.NET exception handling model**, which uses a class hierarchy rooted in `System.Exception`. All exceptions thrown in .NET are objects derived from `System.Exception`.

**Key Components of C# Exception Handling (as covered in the Programming Guide):**

1.  **`try` block:** Defines a block of code where an exception might occur.
2.  **`catch` block:** Contains code to handle a specific type of exception thrown within the preceding `try` block.
3.  **`finally` block:** Contains code that is guaranteed to execute, regardless of whether an exception occurred or was caught. It's crucial for resource cleanup.
4.  **`throw` statement:** Used to explicitly raise an exception.
5.  **Exception Objects:** Instances of classes derived from `System.Exception`, carrying information about the error.
6.  **Exception Filters (C# 6.0+):** Allow you to specify a condition that must be true for a `catch` block to execute.
7.  **`using` statement:** A syntactic sugar for `try-finally` that simplifies resource disposal for objects implementing `IDisposable`.

### Deep Dive with Code Examples:

Let's break down each of these components and their nuances as presented in the C# Programming Guide.

#### 1. The `try` and `catch` Blocks

The fundamental building blocks. `try` encloses the risky code, `catch` handles the specific error.

```csharp
using System;
using System.IO;

namespace ExceptionHandlingGuideDemo
{
    class TryCatchBasics
    {
        public static void DemonstrateBasicCatch()
        {
            Console.WriteLine("\n--- Demonstrate Basic try-catch ---");
            try
            {
                // Simulate an operation that might fail
                string[] lines = File.ReadAllLines("nonExistentFile.txt");
                Console.WriteLine("File read successfully."); // This line won't be reached
            }
            catch (FileNotFoundException ex) // Catch a specific exception
            {
                Console.WriteLine($"Caught: File not found! Message: {ex.Message}");
                // You can log ex.StackTrace here for debugging
            }
            catch (Exception ex) // Catch any other general exception (less specific)
            {
                Console.WriteLine($"Caught: An unexpected error occurred! Type: {ex.GetType().Name}, Message: {ex.Message}");
            }
            Console.WriteLine("Execution continues after try-catch block.");
        }

        public static void DemonstrateMultipleCatches()
        {
            Console.WriteLine("\n--- Demonstrate Multiple Specific Catches ---");
            try
            {
                Console.Write("Enter a number: ");
                string? input = Console.ReadLine();

                if (input == null) throw new ArgumentNullException("Input cannot be null.");

                int value = int.Parse(input); // Can throw FormatException or OverflowException
                Console.WriteLine($"Parsed value: {value}");

                if (value == 0)
                {
                    int divideByZero = 10 / value; // Throws DivideByZeroException
                }
            }
            catch (FormatException ex) // Most specific first
            {
                Console.WriteLine($"Error: Invalid number format. {ex.Message}");
            }
            catch (OverflowException ex) // Next specific
            {
                Console.WriteLine($"Error: Number is too large or too small. {ex.Message}");
            }
            catch (DivideByZeroException ex) // Next specific
            {
                Console.WriteLine($"Error: Attempted to divide by zero. {ex.Message}");
            }
            catch (ArgumentNullException ex) // Catch ArgumentNullException explicitly
            {
                Console.WriteLine($"Error: Argument was null. {ex.Message}");
            }
            catch (Exception ex) // General catch last
            {
                Console.WriteLine($"An unexpected error occurred: {ex.GetType().Name} - {ex.Message}");
            }
            Console.WriteLine("Multiple catch blocks demonstration complete.");
        }

        public static void Run()
        {
            DemonstrateBasicCatch();
            DemonstrateMultipleCatches();

            // Test cases for DemonstrateMultipleCatches:
            // - Enter "abc" (FormatException)
            // - Enter "999999999999999999999999999999999999999999999999" (OverflowException)
            // - Enter "0" (DivideByZeroException)
            // - (Simulate null input, hard to do with ReadLine, but if input was null)
            // - Enter "10" (No exception)
        }
    }
}
```

#### 2. The `finally` Block

Guarantees execution of cleanup code, regardless of exceptions.

```csharp
using System;
using System.IO;

namespace ExceptionHandlingGuideDemo
{
    class FinallyBlockDemo
    {
        public static void ProcessFileWithCleanup(string filePath)
        {
            StreamReader? reader = null; // Use nullable type
            Console.WriteLine($"\n--- Processing file '{filePath}' with finally block ---");
            try
            {
                reader = new StreamReader(filePath);
                string line;
                while ((line = reader.ReadLine()!) != null) // Read lines
                {
                    Console.WriteLine($"Read: {line}");
                    if (line.Contains("error")) // Simulate an error condition
                    {
                        throw new InvalidDataException("Found 'error' keyword in file!");
                    }
                }
            }
            catch (FileNotFoundException ex)
            {
                Console.WriteLine($"Error: File not found. {ex.Message}");
            }
            catch (InvalidDataException ex)
            {
                Console.WriteLine($"Caught specific data error: {ex.Message}");
            }
            catch (Exception ex)
            {
                Console.WriteLine($"An unexpected error occurred: {ex.GetType().Name} - {ex.Message}");
            }
            finally // This block always executes
            {
                if (reader != null)
                {
                    reader.Dispose(); // Equivalent to reader.Close() for StreamReaders
                    Console.WriteLine("Resource (StreamReader) disposed in finally block.");
                }
                else
                {
                    Console.WriteLine("StreamReader was not initialized or was null.");
                }
            }
            Console.WriteLine("Method completed.");
        }

        public static void Run()
        {
            // Create dummy files for demonstration
            string file1 = "good_data.txt";
            File.WriteAllText(file1, "Line 1\nLine 2\nLine 3");
            ProcessFileWithCleanup(file1); // Normal execution

            string file2 = "error_data.txt";
            File.WriteAllText(file2, "Line A\nContains error here\nLine C");
            ProcessFileWithCleanup(file2); // Throws InvalidDataException

            ProcessFileWithCleanup("nonexistent_file.txt"); // Throws FileNotFoundException

            // Clean up dummy files
            File.Delete(file1);
            File.Delete(file2);
        }
    }
}
```

#### 3. The `throw` Statement

Used to explicitly raise an exception.

```csharp
using System;

namespace ExceptionHandlingGuideDemo
{
    class ThrowStatementDemo
    {
        // Method that validates input and throws an exception
        public static void SetUserAge(int age)
        {
            if (age < 0 || age > 120)
            {
                // Throwing a standard .NET exception
                throw new ArgumentOutOfRangeException(nameof(age), $"Age must be between 0 and 120. Provided: {age}");
            }
            Console.WriteLine($"User age set to {age}.");
        }

        // Method that catches, logs, and re-throws (or wraps) an exception
        public static void PerformCriticalOperation()
        {
            Console.WriteLine("\n--- Performing critical operation ---");
            try
            {
                // Simulate an internal error
                int[] numbers = { 1, 2, 3 };
                Console.WriteLine(numbers[5]); // IndexOutOfRangeException
            }
            catch (IndexOutOfRangeException ex)
            {
                Console.WriteLine($"Logger: An array boundary error occurred. Details: {ex.Message}");
                // Option 1: Re-throw the original exception, preserving stack trace
                // throw;

                // Option 2: Wrap the original exception in a new, more descriptive one
                // This is often preferred when you want to provide higher-level context
                throw new InvalidOperationException("Failed to complete critical operation due to internal data access error.", ex);
            }
        }

        public static void Run()
        {
            try
            {
                SetUserAge(30);
                SetUserAge(150); // This will throw ArgumentOutOfRangeException
            }
            catch (ArgumentOutOfRangeException ex)
            {
                Console.WriteLine($"Caught in main: {ex.Message}");
            }

            try
            {
                PerformCriticalOperation();
            }
            catch (InvalidOperationException ex) // Catches the wrapped exception
            {
                Console.WriteLine($"Caught in main: {ex.Message}");
                if (ex.InnerException != null)
                {
                    Console.WriteLine($"Inner Exception: {ex.InnerException.GetType().Name} - {ex.InnerException.Message}");
                    Console.WriteLine($"Inner Stack Trace: {ex.InnerException.StackTrace}");
                }
            }
        }
    }
}
```

#### 4. Exception Objects and the Exception Class Hierarchy

All exceptions derive from `System.Exception`. Key properties include `Message`, `StackTrace`, `InnerException`, `HelpLink`, `HResult`.

```csharp
using System;

namespace ExceptionHandlingGuideDemo
{
    class ExceptionObjectProperties
    {
        public static void CauseAndCatchException()
        {
            Console.WriteLine("\n--- Exploring Exception Object Properties ---");
            try
            {
                // Cause a NullReferenceException
                string? s = null;
                s!.Contains("hello"); // Using null-forgiving operator to force NRE
            }
            catch (NullReferenceException ex)
            {
                Console.WriteLine($"Exception Type: {ex.GetType().Name}");
                Console.WriteLine($"Message: {ex.Message}");
                Console.WriteLine($"Stack Trace:\n{ex.StackTrace}");
                Console.WriteLine($"Target Site: {ex.TargetSite?.Name}"); // The method where exception occurred
                Console.WriteLine($"Source: {ex.Source}"); // The assembly where the exception originated
                Console.WriteLine($"Help Link: {ex.HelpLink ?? "N/A"}"); // Often null for custom code
                Console.WriteLine($"HResult: {ex.HResult}"); // Numeric value for the exception
            }

            try
            {
                // Demonstrate InnerException
                try
                {
                    throw new FileNotFoundException("Original file was missing.", "my_config.txt");
                }
                catch (FileNotFoundException innerEx)
                {
                    throw new ApplicationException("Could not start application due to missing configuration.", innerEx);
                }
            }
            catch (ApplicationException outerEx)
            {
                Console.WriteLine($"\nCaught Outer Exception: {outerEx.Message}");
                Console.WriteLine($"Outer Stack Trace:\n{outerEx.StackTrace}");
                if (outerEx.InnerException != null)
                {
                    Console.WriteLine($"\nInner Exception Type: {outerEx.InnerException.GetType().Name}");
                    Console.WriteLine($"Inner Exception Message: {outerEx.InnerException.Message}");
                    Console.WriteLine($"Inner Exception Stack Trace:\n{outerEx.InnerException.StackTrace}");
                }
            }
        }

        public static void Run()
        {
            CauseAndCatchException();
        }
    }
}
```

#### 5. Exception Filters (C# 6.0+)

Allow you to add a condition to a `catch` block using a `when` clause. The `catch` block is only executed if the condition is true. This is processed *before* the exception handler itself, leading to more efficient error handling.

```csharp
using System;
using System.Net.Http; // For HttpRequestException

namespace ExceptionHandlingGuideDemo
{
    class ExceptionFiltersDemo
    {
        public static void SimulateWebCall(int statusCode)
        {
            Console.WriteLine($"\n--- Simulating Web Call with Status Code: {statusCode} ---");
            try
            {
                if (statusCode >= 400)
                {
                    throw new HttpRequestException($"HTTP error occurred: {statusCode}");
                }
                Console.WriteLine("Web call successful.");
            }
            catch (HttpRequestException ex) when (statusCode == 404) // Filter: only catch 404 errors
            {
                Console.WriteLine($"Caught: HTTP 404 Not Found. Message: {ex.Message}");
            }
            catch (HttpRequestException ex) when (statusCode >= 500) // Filter: only catch server errors
            {
                Console.WriteLine($"Caught: HTTP Server Error. Message: {ex.Message}");
            }
            catch (HttpRequestException ex) // Catches any other HttpRequestException not filtered above
            {
                Console.WriteLine($"Caught: Other HTTP error. Message: {ex.Message}");
            }
            catch (Exception ex)
            {
                Console.WriteLine($"Caught: Unexpected general error. {ex.Message}");
            }
            Console.WriteLine("Web call simulation complete.");
        }

        public static void Run()
        {
            SimulateWebCall(200); // Success
            SimulateWebCall(404); // Catches specific 404 filter
            SimulateWebCall(500); // Catches specific 5xx filter
            SimulateWebCall(401); // Catches general HttpRequestException
        }
    }
}
```

#### 6. The `using` Statement (for `IDisposable` Objects)

A convenient syntactic sugar for a `try-finally` block, ensuring that `Dispose()` is called on objects that implement `IDisposable` (primarily for resources like files, network connections, database connections).

```csharp
using System;
using System.IO;

namespace ExceptionHandlingGuideDemo
{
    class UsingStatementDemo
    {
        public static void ReadFileUsingStatement(string filePath)
        {
            Console.WriteLine($"\n--- Reading file '{filePath}' using 'using' statement ---");
            try
            {
                // The StreamReader is automatically disposed when exiting the 'using' block,
                // even if an exception occurs. This is syntactic sugar for try-finally.
                using (StreamReader reader = new StreamReader(filePath))
                {
                    string content = reader.ReadToEnd();
                    Console.WriteLine($"File content (first 50 chars): {content.Substring(0, Math.Min(content.Length, 50))}");
                    // Simulate an error after reading
                    if (content.Length > 10)
                    {
                        throw new InvalidOperationException("Content too long for further processing!");
                    }
                } // reader.Dispose() is called here automatically
            }
            catch (FileNotFoundException ex)
            {
                Console.WriteLine($"Error: File not found. {ex.Message}");
            }
            catch (InvalidOperationException ex)
            {
                Console.WriteLine($"Caught: Invalid operation on content. {ex.Message}");
            }
            catch (Exception ex)
            {
                Console.WriteLine($"An unexpected error occurred: {ex.GetType().Name} - {ex.Message}");
            }
            Console.WriteLine("Method completed (using statement ensures disposal).");
        }

        public static void Run()
        {
            string file = "small_data.txt";
            File.WriteAllText(file, "Short content.");
            ReadFileUsingStatement(file);

            string longFile = "long_data.txt";
            File.WriteAllText(longFile, "This is a very long content string for demonstration purposes.");
            ReadFileUsingStatement(longFile); // Will throw InvalidOperationException

            ReadFileUsingStatement("nonexistent_file_for_using.txt"); // Will throw FileNotFoundException

            File.Delete(file);
            File.Delete(longFile);
        }
    }
}
```

### Main Program to Run All Demos:

```csharp
using System;

namespace ExceptionHandlingGuideDemo
{
    class Program
    {
        static void Main(string[] args)
        {
            Console.WriteLine("--- Exception Handling (C# Programming Guide) ---");

            TryCatchBasics.Run();
            FinallyBlockDemo.Run();
            ThrowStatementDemo.Run();
            ExceptionObjectProperties.Run();
            ExceptionFiltersDemo.Run();
            UsingStatementDemo.Run();

            Console.WriteLine("\n--- End of Exception Handling Guide Demo ---");
            Console.ReadKey();
        }
    }
}
```

### Key Takeaways from "Exception Handling (C# Programming Guide)":

* **Structured Error Handling:** The guide emphasizes that C#'s `try-catch-finally` model provides a robust and structured way to separate error-handling code from normal program logic.
* **Exception Hierarchy:** Understanding the `System.Exception` hierarchy is crucial for effective catching (from most specific to least specific).
* **Resource Management:** The `finally` block and the `using` statement are paramount for ensuring proper resource cleanup, preventing leaks and deadlocks.
* **Throwing Correctly:** The guide reinforces the proper use of `throw` (especially `throw;` for re-throwing) and the importance of providing meaningful exception messages and inner exceptions.
* **Exception Filters:** Highlighted as a powerful feature for conditional exception handling, improving code clarity and efficiency.
* **Performance Considerations:** While not explicitly shown in every example, the guide implicitly or explicitly reminds developers that exceptions are generally more expensive than normal control flow. This reinforces the "use exceptions for exceptional circumstances" principle.

This "Programming Guide" document provides a holistic view of the exception handling mechanism in C#, covering its syntax, semantics, and common usage patterns for building resilient applications.